Workbook

Sheet Входные
A1: ДЗ 4 — калькулятор сайзинга. Сервис бронирования отелей
A2: Меняйте только СИНИЕ ячейки в столбце B (жёлтая заливка — ключевые допущения). Все остальные листы пересчитаются.
A4: Параметр | B4: Значение | C4: Ед. | D4: Источник / обоснование
A5: АУДИТОРИЯ
A6: MAU | B6: 3000000 | C6: чел. | D6: Задание ДЗ 4
A7: DAU | B7: 300000 | C7: чел. | D7: Задание ДЗ 4
A8: Бронирований на MAU в месяц | B8: 1 | C8: шт. | D8: Задание ДЗ 4
A9: Бронирований в сутки | B9: =B6*B8/30 -> 100000 | C9: шт. | D9: MAU × броней в месяц ÷ 30
A10: Сессий на DAU в сутки | B10: 1.3 | C10: шт. | D10: Допущение: часть пользователей возвращается в течение дня
A11: ВОРОНКА (действий за сессию)
A12: Автодополнение города | B12: 6 | C12: шт. | D12: debounce при наборе
A13: Поисковая выдача (SERP) | B13: 5 | C13: шт. | D13: уточнение дат и фильтров
A14: Карточка отеля | B14: 3 | C14: шт. | D14: из ~20 отелей выдачи открывают 3
A15: Календарь / проверка доступности | B15: 4 | C15: шт. | D15: внутри карточки
A16: Профиль, «мои брони» | B16: 1 | C16: шт.
A17: КОЭФФИЦИЕНТЫ ПИКОВ
A18: k_сут (внутрисуточный) | B18: 2 | C18: × | D18: ~40% суточного трафика за 4 вечерних часа
A19: k_сезон | B19: 5 | C19: × | D19: Задание ДЗ 4: пик в сезон отпусков
A20: k_пик итоговый | B20: =B18*B19 -> 10 | C20: × | D20: k_сут × k_сезон
A21: k_CM (channel manager) | B21: 3 | C21: × | D21: B2B-поток слабо зависит от сезона
A22: КАТАЛОГ И B2B-ПОТОК
A23: Отелей в каталоге | B23: 200000 | C23: шт. | D23: Из ДЗ 3; зависит от рынка, а не от аудитории
A24: Типов номеров на отель | B24: 8 | C24: шт. | D24: Из ДЗ 3
A25: Тарифных планов на тип номера | B25: 2 | C25: шт. | D25: невозвратный + со свободной отменой
A26: Горизонт продаж | B26: 540 | C26: дней | D26: 18 месяцев вперёд
A27: Обновлений ячеек на отель в сутки | B27: 400 | C27: шт. | D27: ~5% календаря; САМЫЙ ЧУВСТВИТЕЛЬНЫЙ параметр модели
A28: Строк в одном батче channel manager | B28: 100 | C28: шт. | D28: размер батча API партнёра
A29: ТЕХНИЧЕСКИЕ
A30: Целевая утилизация CPU | B30: 0.6 | D30: выше — растёт p99 из-за очередей
A31: vCPU на под приложения | B31: 2 | C31: шт.
A32: Рост аудитории и каталога в год | B32: 0.2 | D32: для горизонта 1 и 3 года
A33: Часов в месяце | B33: 730 | C33: ч | D33: 24 × 365 ÷ 12
A34: Хит-рейт кэша: автодополнение | B34: 0.9 | D34: Из ДЗ 3
A35: Хит-рейт кэша: SERP | B35: 0.6 | D35: Из ДЗ 3, TTL 60 с
A36: Хит-рейт кэша: доступность | B36: 0.9 | D36: Из ДЗ 3, TTL 30 с
A37: ЦЕНЫ, Yandex Cloud (прайс-лист, с НДС)
A38: vCPU (Ice Lake, 100%) | B38: 1.15 | C38: ₽/ч | D38: Проверять в калькуляторе провайдера перед защитой бюджета
A39: RAM | B39: 0.31 | C39: ₽/ГБ·ч
A40: Диск network-SSD | B40: 11.3 | C40: ₽/ГБ·мес
A41: Диск non-replicated SSD | B41: 5.7 | C41: ₽/ГБ·мес
...

Sheet RPS
A1: 1. Расчёт RPS
A2: RPS_avg = Объём_сут / 86 400 · RPS_peak = RPS_avg × k_пик
A4: Эндпоинт | B4: Тип | C4: Формула объёма в сутки | D4: Объём/сут | E4: RPS avg | F4: RPS peak
A5: GET /autocomplete | B5: чтение | C5: DAU × сессий × автодополнений | D5: =ROUND(Входные!$B$7*Входные!$B$10*Входные!$B$12,0) -> 2340000 | E5: =D5/86400 -> 27.083333 | F5: =E5*Входные!$B$20 -> 270.83333
A6: POST /graphql searchHotels (SERP) | B6: чтение | C6: DAU × сессий × SERP | D6: =ROUND(Входные!$B$7*Входные!$B$10*Входные!$B$13,0) -> 1950000 | E6: =D6/86400 -> 22.569444 | F6: =E6*Входные!$B$20 -> 225.69444
A7: GET /hotels/{id} (карточка) | B7: чтение | C7: DAU × сессий × карточек | D7: =ROUND(Входные!$B$7*Входные!$B$10*Входные!$B$14,0) -> 1170000 | E7: =D7/86400 -> 13.541667 | F7: =E7*Входные!$B$20 -> 135.41667
A8: CheckAvailability (календарь) | B8: чтение | C8: DAU × сессий × проверок | D8: =ROUND(Входные!$B$7*Входные!$B$10*Входные!$B$15,0) -> 1560000 | E8: =D8/86400 -> 18.055556 | F8: =E8*Входные!$B$20 -> 180.55556
A9: GET /users/me/bookings | B9: чтение | C9: DAU × сессий × просмотров профиля | D9: =ROUND(Входные!$B$7*Входные!$B$10*Входные!$B$16,0) -> 390000 | E9: =D9/86400 -> 4.5138889 | F9: =E9*Входные!$B$20 -> 45.138889
A10: CreateHold | B10: запись | C10: броней/сут × 1,5 (часть холдов истекает) | D10: =ROUND(Входные!$B$9*1.5,0) -> 150000 | E10: =D10/86400 -> 1.7361111 | F10: =E10*Входные!$B$20 -> 17.361111
A11: ReleaseHold | B11: запись | C11: истёкшие и отменённые холды | D11: =ROUND(Входные!$B$9*0.5,0) -> 50000 | E11: =D11/86400 -> 0.5787037 | F11: =E11*Входные!$B$20 -> 5.787037
A12: POST /v1/bookings | B12: запись | C12: из задания | D12: =Входные!$B$9 -> 100000 | E12: =D12/86400 -> 1.1574074 | F12: =E12*Входные!$B$20 -> 11.574074
A13: DELETE /v1/bookings/{id} | B13: запись | C13: 15% отмен | D13: =ROUND(Входные!$B$9*0.15,0) -> 15000 | E13: =D13/86400 -> 0.17361111 | F13: =E13*Входные!$B$20 -> 1.7361111
A14: Payment authorize/capture/refund | B14: запись | C14: 2,1 операции на бронь | D14: =ROUND(Входные!$B$9*2.1,0) -> 210000 | E14: =D14/86400 -> 2.4305556 | F14: =E14*Входные!$B$20 -> 24.305556
A15: Channel manager (батчи) | B15: запись | C15: строк/сут ÷ размер батча | D15: =D16/Входные!$B$28 -> 800000 | E15: =D15/86400 -> 9.2592593 | F15: =E15*Входные!$B$21 -> 27.777778
A16: ↳ строк календаря | B16: запись | C16: отелей × обновлений на отель в сутки | D16: =Входные!$B$23*Входные!$B$27 -> 80000000 | E16: =D16/86400 -> 925.92593 | F16: =E16*Входные!$B$21 -> 2777.7778
A18: ИТОГО через API Gateway | C18: чтение + запись + батчи CM (без строк календаря) | D18: =SUM(D5:D14)+D15 -> 8735000 | E18: =SUM(E5:E14)+E15 -> 101.09954 | F18: =SUM(F5:F14)+F15 -> 946.18056
A19: Read / Write на API | C19: чтение ÷ запись | D19: =SUM(D5:D9)/SUM(D10:D14) -> 14.114286
A21: Производные нагрузки (после кэшей из ДЗ 3)
A22: Компонент | C22: Формула | F22: Пик
A23: Elasticsearch, QPS | C23: автодоп.×(1−hit) + SERP×(1−hit) | F23: =F5*(1-Входные!$B$34)+F6*(1-Входные!$B$35) -> 117.36111
A24: Inventory PG, чтение RPS | C24: (календарь + карточка)×(1−hit) | F24: =(F8+F7)*(1-Входные!$B$36) -> 31.597222
A25: Inventory PG, запись строк/с | C25: тx/с × 3 ночи + строки channel manager | F25: =(F10+F11+F12+F13)*3+F16 -> 2887.1528
A26: Booking PG, запись строк/с | C26: брони × 6 (бронь + переходы статуса) | F26: =F12*6+F13*3 -> 74.652778
A27: Redis, ops/s | C27: чтения × 1,5 + rate-limit + сессии | F27: =SUM(F5:F9)*1.5+F18*2 -> 3178.8194
A28: Внутренние gRPC, RPS | C28: fan-out 1,8 на внешний запрос | F28: =F18*1.8 -> 1703.125

Sheet Хранилище
A1: 2. Расчёт хранилища
A2: Объём = N_строк × S_строки × k_индексы × k_bloat. Для ScyllaDB — × RF × запас на compaction.
A4: Хранилище | B4: Формула количества строк/объектов | C4: Строк / объектов | D4: Байт на строку | E4: Объём сейчас, ГБ | F4: Через 1 год, ГБ | G4: Через 3 года, ГБ | H4: Характер роста
A5: Inventory PG: календарь | B5: отели × типы × горизонт | C5: =Входные!$B$23*Входные!$B$24*Входные!$B$26 -> 864000000 | D5: 230 | E5: =C5*D5*1/10^9 -> 198.72 | F5: =E5*(1+Входные!$B$32) -> 238.464 | G5: =E5*(1+Входные!$B$32)^3 -> 343.38816 | H5: окно 540 дней, растёт только с каталогом
A6: Inventory PG: holds | B6: холдов/сут × 30 дней хранения | C6: =RPS!D10*30 -> 4500000 | D6: 250 | E6: =C6*D6*1/10^9 -> 1.125 | F6: =E6*(1+Входные!$B$32) -> 1.35 | G6: =E6*(1+Входные!$B$32)^3 -> 1.944 | H6: TTL
A7: Booking PG: брони + saga_instance | B7: MAU × броней/мес × 12 | C7: =Входные!$B$6*Входные!$B$8*12 -> 36000000 | D7: 1125 | E7: =C7*D7*1/10^9 -> 40.5 | F7: =E7 -> 40.5 | G7: =E7*((1+Входные!$B$32)^3-1)/Входные!$B$32 -> 147.42 | H7: retention 5 лет
A8: Booking PG: лог переходов | B8: броней в год × 6 переходов | C8: =C7*6 -> 216000000 | D8: 250 | E8: =C8*D8*1/10^9 -> 54 | F8: =E8 -> 54 | G8: =E8*((1+Входные!$B$32)^3-1)/Входные!$B$32 -> 196.56 | H8: append-only
A9: Payment PG: платежи | B9: 1 платёж на бронь | C9: =C7 -> 36000000 | D9: 800 | E9: =C9*D9*1/10^9 -> 28.8 | F9: =E9 -> 28.8 | G9: =E9*((1+Входные!$B$32)^3-1)/Входные!$B$32 -> 104.832 | H9: партиции по месяцам
A10: Payment PG: попытки PSP (90 дней) | B10: броней × 1,3 попытки × 25% года | C10: =C7*1.3*0.25 -> 11700000 | D10: 3000 | E10: =C10*D10*1/10^9 -> 35.1 | F10: =E10*(1+Входные!$B$32) -> 42.12 | G10: =E10*(1+Входные!$B$32)^3 -> 60.6528 | H10: остальное — в Object Storage
A11: Pricing Scylla: rate_calendar | B11: отели × типы × тарифы × горизонт | C11: =Входные!$B$23*Входные!$B$24*Входные!$B$25*Входные!$B$26 -> 1728000000 | D11: 40 | E11: =C11*D11*4.5/10^9 -> 311.04 | F11: =E11*(1+Входные!$B$32) -> 373.248 | G11: =E11*(1+Входные!$B$32)^3 -> 537.47712 | H11: × RF3 × 1,5 (compaction)
A12: Search ES: hotel_doc | B12: документов = отелей | C12: =Входные!$B$23 -> 200000 | D12: 50000 | E12: =C12*D12*6/10^9 -> 60 | F12: =E12*(1+Входные!$B$32) -> 72 | G12: =E12*(1+Входные!$B$32)^3 -> 103.68 | H12: × 2 (индексы) × RF2 × 1,5
A13: Notification Scylla | B13: броней × 3,5 уведомл. × 180/365 дней | C13: =C7*3.5*180/365 -> 62136986 | D13: 300 | E13: =C13*D13*3/10^9 -> 55.923288 | F13: =E13*(1+Входные!$B$32) -> 67.107945 | G13: =E13*(1+Входные!$B$32)^3 -> 96.635441 | H13: × RF3, TTL 180 дней
A14: ClickHouse: события | B14: 9,5 млн событий/сут × 365 | C14: =9500000*365 -> 3467500000 | D14: 40 | E14: =C14*D14*1/10^9 -> 138.7 | F14: =E14 -> 138.7 | G14: =E14*((1+Входные!$B$32)^3-1)/Входные!$B$32 -> 504.868 | H14: сжатие ~10×, TTL деталей 12 мес
A15: Kafka | B15: 9,5 млн событий/сут × 7 дней retention | C15: =9500000*7 -> 66500000 | D15: 600 | E15: =C15*D15*3/10^9 -> 119.7 | F15: =E15*(1+Входные!$B$32) -> 143.64 | G15: =E15*(1+Входные!$B$32)^3 -> 206.8416 | H15: × RF3
A16: S3: фото | B16: отели × 20 фото × 3 размера | C16: =Входные!$B$23*20*3 -> 12000000 | D16: 133000 | E16: =C16*D16*1/10^9 -> 1596 | F16: =E16*(1+Входные!$B$32) -> 1915.2 | G16: =E16*(1+Входные!$B$32)^3 -> 2757.888 | H16: растёт с каталогом
A17: Redis (RAM) | B17: SERP 8 + карточки 4 + сессии 3 + прочее 1 | E17: 16 | F17: =E17*(1+Входные!$B$32) -> 19.2 | G17: =E17*(1+Входные!$B$32)^3 -> 27.648 | H17: окно
A18: ИТОГО «горячих» данных (без S3) | E18: =SUM(E5:E15)+E17 -> 1059.6083 | F18: =SUM(F5:F15)+F17 -> 1219.1299 | G18: =SUM(G5:G15)+G17 -> 2331.9471
A19: ИТОГО S3 | E19: =E16 -> 1596 | F19: =F16 -> 1915.2 | G19: =G16 -> 2757.888
A21: Множители k_индексы×k_bloat / RF заложены в столбец «Объём»: PG ×1, Scylla ×4,5 (RF3×1,5), ES ×6, Kafka ×3.

Sheet Bandwidth
A1: 3. Расчёт bandwidth
A2: Мбит/с = Объём_байт_сут × 8 / 86 400 / 10⁶
A4: Поток | B4: Формула | C4: Объём/сут, ГБ | D4: avg, Мбит/с | E4: peak, Мбит/с | F4: Оплачиваемо, ГБ/мес
A5: Медиа: превью в выдаче | B5: SERP × 15 картинок × 40 КБ | C5: =RPS!D6*15*40000/10^9 -> 1170 | D5: =C5*8*1000/86400 -> 108.33333 | E5: =D5*Входные!$B$20 -> 1083.3333 | F5: =C5*30 -> 35100
A6: Медиа: фото карточки | B6: карточек × 10 фото × 200 КБ | C6: =RPS!D7*10*200000/10^9 -> 2340 | D6: =C6*8*1000/86400 -> 216.66667 | E6: =D6*Входные!$B$20 -> 2166.6667 | F6: =C6*30 -> 70200
A7: API JSON (сырой) | B7: SERP×60КБ + карточка×40КБ + календарь×8КБ + автодоп×2КБ + профиль×20КБ | C7: =(RPS!D6*60000+RPS!D7*40000+RPS!D8*8000+RPS!D5*2000+RPS!D9*20000)/10^9 -> 188.76 | D7: =C7*8*1000/86400 -> 17.477778 | E7: =D7*Входные!$B$20 -> 174.77778 | F7: =C7*30 -> 5662.8
A8: API JSON после gzip ×5 | B8: сырой ÷ 5 | C8: =C7/5 -> 37.752 | D8: =C8*8*1000/86400 -> 3.4955556 | E8: =D8*Входные!$B$20 -> 34.955556 | F8: =C8*30 -> 1132.56
A9: Медиа всего (через CDN) | B9: превью + фото | C9: =C5+C6 -> 3510 | D9: =C9*8*1000/86400 -> 325 | E9: =D9*Входные!$B$20 -> 3250 | F9: =C9*30 -> 105300
A10: Origin (промах CDN 5% + API) | B10: медиа × 5% + API gzip | C10: =C9*0.05+C8 -> 213.252 | D10: =C10*8*1000/86400 -> 19.745556 | E10: =D10*Входные!$B$20 -> 197.45556 | F10: =C10*30 -> 6397.56
A11: Внутренний (gRPC + Kafka + репликация) | B11: ~3× API | C11: =C8*3 -> 113.256 | D11: =C11*8*1000/86400 -> 10.486667 | E11: =D11*Входные!$B$20 -> 104.86667
A13: ИТОГО полоса на пике, Гбит/с | E13: =(E9+E10)/1000 -> 3.4474556

Sheet Ресурсы
A1: 4. Оценка ресурсов
A2: N_подов = ⌈(RPS_peak × t_cpu) / (vCPU_под × утилизация)⌉, но не меньше HA-минимума
A4: Сервис | B4: Что обслуживает на пике | C4: t_cpu, мс | D4: CPU-мс/с | E4: vCPU нужно | F4: HA-минимум | G4: Подов
A5: API Gateway | B5: весь внешний трафик | C5: 3 | D5: =RPS!F18*C5 -> 2838.5417 | E5: =D5/1000/Входные!$B$30 -> 4.7309028 | F5: 3 | G5: =MAX(F5,CEILING(E5/Входные!$B$31,1)) -> 3
A6: Search | B6: автодополнение (1 мс) + SERP (6 мс) | C6: 6 | D6: =RPS!F5*1+RPS!F6*6 -> 1625 | E6: =D6/1000/Входные!$B$30 -> 2.7083333 | F6: 3 | G6: =MAX(F6,CEILING(E6/Входные!$B$31,1)) -> 3
A7: Inventory | B7: календарь, карточка, холды, батчи CM (40 мс) | C7: 3 | D7: =RPS!F8*3+RPS!F7*2+(RPS!F10+RPS!F11)*5+RPS!F12*5+RPS!F15*40 -> 2097.2222 | E7: =D7/1000/Входные!$B$30 -> 3.4953704 | F7: 3 | G7: =MAX(F7,CEILING(E7/Входные!$B$31,1)) -> 3
A8: Pricing | B8: обогащение выдачи и карточек + запись тарифов | C8: 4 | D8: =RPS!F6*4+RPS!F7*4+RPS!F8*3+RPS!F15*30 -> 2819.4444 | E8: =D8/1000/Входные!$B$30 -> 4.6990741 | F8: 3 | G8: =MAX(F8,CEILING(E8/Входные!$B$31,1)) -> 3
A9: Booking | B9: оркестрация Saga | C9: 25 | D9: =RPS!F12*25+RPS!F13*20 -> 324.07407 | E9: =D9/1000/Входные!$B$30 -> 0.54012346 | F9: 3 | G9: =MAX(F9,CEILING(E9/Входные!$B$31,1)) -> 3
A10: Payment | B10: authorize / capture / refund | C10: 15 | D10: =RPS!F14*15 -> 364.58333 | E10: =D10/1000/Входные!$B$30 -> 0.60763889 | F10: 3 | G10: =MAX(F10,CEILING(E10/Входные!$B$31,1)) -> 3
A11: User/Identity | B11: профиль + логины | C11: 3 | D11: =RPS!F9*3+20*10 -> 335.41667 | E11: =D11/1000/Входные!$B$30 -> 0.55902778 | F11: 3 | G11: =MAX(F11,CEILING(E11/Входные!$B$31,1)) -> 3
A12: Notification | B12: отправка уведомлений | C12: 10 | D12: =40*10 -> 400 | E12: =D12/1000/Входные!$B$30 -> 0.66666667 | F12: 2 | G12: =MAX(F12,CEILING(E12/Входные!$B$31,1)) -> 2
A13: Инфра-поды | B13: Debezium, hold-sweeper, планировщик, агенты | E13: 7 | F13: 7 | G13: 7
A14: ИТОГО | D14: =SUM(D5:D12) -> 10804.282 | E14: =SUM(E5:E13) -> 25.007137 | G14: =SUM(G5:G13) -> 30
A16: vCPU запрошено | B16: подов приложений × vCPU на под + инфра | E16: =SUM(G5:G12)*Входные!$B$31+G13 -> 53
A17: RAM запрошено, ГБ | B17: подов × 4 ГБ + инфра × 2 ГБ | E17: =SUM(G5:G12)*4+G13*2 -> 106
A18: Нод k8s 8 vCPU / 32 ГБ (пик) | B18: max(по CPU, по RAM) при утилизации 80% | E18: =MAX(3,CEILING(E16/0.8/8,1),CEILING(E17/0.8/32,1)) -> 9
A19: Нод k8s вне сезона | B19: HA-минимум 2 реплики на сервис | E19: 5

Sheet Стоимость
A1: 5. Расчёт стоимости (Yandex Cloud, прайс-лист с НДС, без CUD)
A2: Узел ₽/мес = (vCPU × цена_vCPU + RAM × цена_RAM) × 730 ч × надбавка_managed + Диск × цена_диска
A4: Компонент | B4: Узлов | C4: vCPU | D4: RAM, ГБ | E4: Диск, ГБ | F4: Цена диска, ₽/ГБ·мес | G4: Managed | H4: ₽/мес
A5: Kubernetes: воркеры (пик сезона) | B5: =Ресурсы!E18 -> 9 | C5: 8 | D5: 32 | E5: 100 | F5: =Входные!$B$40 -> 11.3 | G5: 1 | H5: =B5*((C5*Входные!$B$38+D5*Входные!$B$39)*Входные!$B$33*G5+E5*F5) -> 135788.4
A6: Inventory PostgreSQL: 2 шарда × 3 узла | B6: 6 | C6: 8 | D6: 32 | E6: 500 | F6: =Входные!$B$40 -> 11.3 | G6: =Входные!$B$46 -> 1.25 | H6: =B6*((C6*Входные!$B$38+D6*Входные!$B$39)*Входные!$B$33*G6+E6*F6) -> 138582
A7: Booking PostgreSQL: 1 шард × 3 узла | B7: 3 | C7: 4 | D7: 16 | E7: 700 | F7: =Входные!$B$40 -> 11.3 | G7: =Входные!$B$46 -> 1.25 | H7: =B7*((C7*Входные!$B$38+D7*Входные!$B$39)*Входные!$B$33*G7+E7*F7) -> 49900.5
A8: Payment PostgreSQL: 3 узла (PCI-контур) | B8: 3 | C8: 4 | D8: 16 | E8: 400 | F8: =Входные!$B$40 -> 11.3 | G8: =Входные!$B$46 -> 1.25 | H8: =B8*((C8*Входные!$B$38+D8*Входные!$B$39)*Входные!$B$33*G8+E8*F8) -> 39730.5
A9: User PostgreSQL: 3 узла | B9: 3 | C9: 2 | D9: 8 | E9: 100 | F9: =Входные!$B$40 -> 11.3 | G9: =Входные!$B$46 -> 1.25 | H9: =B9*((C9*Входные!$B$38+D9*Входные!$B$39)*Входные!$B$33*G9+E9*F9) -> 16475.25
A10: Pricing + Notification ScyllaDB: 3 узла | B10: 3 | C10: 8 | D10: 32 | E10: 700 | F10: =Входные!$B$41 -> 5.7 | G10: 1 | H10: =B10*((C10*Входные!$B$38+D10*Входные!$B$39)*Входные!$B$33*G10+E10*F10) -> 53842.8
A11: Elasticsearch: 3 узла | B11: 3 | C11: 8 | D11: 32 | E11: 150 | F11: =Входные!$B$40 -> 11.3 | G11: =Входные!$B$46 -> 1.25 | H11: =B11*((C11*Входные!$B$38+D11*Входные!$B$39)*Входные!$B$33*G11+E11*F11) -> 57426
A12: Redis: кэш 2 × 16 ГБ | B12: 2 | C12: 2 | D12: 16 | E12: 0 | F12: =Входные!$B$40 -> 11.3 | G12: =Входные!$B$46 -> 1.25 | H12: =B12*((C12*Входные!$B$38+D12*Входные!$B$39)*Входные!$B$33*G12+E12*F12) -> 13249.5
A13: Redis: state 2 × 8 ГБ (AOF) | B13: 2 | C13: 2 | D13: 8 | E13: 20 | F13: =Входные!$B$40 -> 11.3 | G13: =Входные!$B$46 -> 1.25 | H13: =B13*((C13*Входные!$B$38+D13*Входные!$B$39)*Входные!$B$33*G13+E13*F13) -> 9175.5
A14: Kafka: 3 брокера | B14: 3 | C14: 4 | D14: 16 | E14: 200 | F14: =Входные!$B$40 -> 11.3 | G14: =Входные!$B$46 -> 1.25 | H14: =B14*((C14*Входные!$B$38+D14*Входные!$B$39)*Входные!$B$33*G14+E14*F14) -> 32950.5
A15: RabbitMQ: 3 узла | B15: 3 | C15: 2 | D15: 8 | E15: 50 | F15: =Входные!$B$40 -> 11.3 | G15: =Входные!$B$46 -> 1.25 | H15: =B15*((C15*Входные!$B$38+D15*Входные!$B$39)*Входные!$B$33*G15+E15*F15) -> 14780.25
A16: ClickHouse: 2 узла | B16: 2 | C16: 8 | D16: 32 | E16: 700 | F16: =Входные!$B$42 -> 3.25 | G16: =Входные!$B$46 -> 1.25 | H16: =B16*((C16*Входные!$B$38+D16*Входные!$B$39)*Входные!$B$33*G16+E16*F16) -> 39444
A17: Kubernetes: региональный мастер + балансировщик | F17: фикс. стоимость управляющего слоя | H17: 7500
A18: CDN | F18: медиатрафик × цена CDN | H18: =Bandwidth!F9*Входные!$B$45 -> 105300
A19: Исходящий трафик с origin | F19: origin egress × цена | H19: =Bandwidth!F10*Входные!$B$44 -> 6269.6088
A20: Object Storage: фото + архив | F20: объём S3 × цена | H20: =(Хранилище!F16+120)*Входные!$B$43 -> 4070.4
A21: Логи, мониторинг, бэкапы | F21: оценка | H21: 25000
A22: ИТОГО, ₽/мес | H22: =SUM(H5:H21) -> 749485.21
A23: ИТОГО, млн ₽/год | H23: =H22*12/10^6 -> 8.9938225
A24: Стоимость одной брони, ₽ | H24: =H22/(Входные!$B$6*Входные!$B$8) -> 0.2498284

Sheet Оптимизация
A1: 6. Оптимизация
A2: Экономия считается от базовой сметы на листе «Стоимость»
A4: Мера | B4: Как считается экономия | C4: ₽/мес | D4: % сметы
A5: 1. AVIF/WebP + srcset + lazy-load | B5: превью 40→15 КБ, фото 200→90 КБ: CDN 105→47 ТБ + половина origin egress | C5: =Стоимость!H18*(1-(RPS!D6*15*15000+RPS!D7*10*90000)/(RPS!D6*15*40000+RPS!D7*10*200000))+Стоимость!H19*0.5 -> 63682.304 | D5: =C5/Стоимость!H22 -> 0.08496806
A6: 2. CUD на 1 год для БД и 5 базовых нод k8s | B6: −30% на compute-часть (≈75% стоимости узла) баз и базовых нод | C6: =(SUM(Стоимость!H6:H16)*0.75+Стоимость!H5*5/Ресурсы!E18)*0.3 -> 127381.68 | D6: =C6/Стоимость!H22 -> 0.1699589
A7: 3. HPA/CA: пиковые ноды 2 мес/год + прерываемые ВМ | B7: (нод_пик − нод_база) × цена узла × (1 − 2/12 × 0,5) | C7: =(Стоимость!H5/Ресурсы!E18)*(Ресурсы!E18-Ресурсы!E19)*(1-2/12*0.5) -> 55321.2 | D7: =C7/Стоимость!H22 -> 0.073812264
A8: 4. Tiered storage: архив партиций в Object Storage | B8: 35% диска Inventory + 50% диска Payment + часть логов уходят с SSD | C8: =Стоимость!E6*Стоимость!F6*Стоимость!B6*0.35+Стоимость!E8*Стоимость!F8*Стоимость!B8*0.5+12000 -> 30645 | D8: =C8/Стоимость!H22 -> 0.040888065
A9: 5. Хит-рейт SERP 60%→80%: ES 3×(8/32) → 3×(4/16) | B9: нормализация ключа кэша + прогрев топ-20 городов | C9: =Стоимость!H11-3*((4*Входные!$B$38+16*Входные!$B$39)*Входные!$B$33*Входные!$B$46+150*Входные!$B$40) -> 26170.5 | D9: =C9/Стоимость!H22 -> 0.034917967
A10: ИТОГО экономия | C10: =SUM(C5:C9) -> 303200.68 | D10: =C10/Стоимость!H22 -> 0.40454525
A11: Стоимость после оптимизации, ₽/мес | C11: =Стоимость!H22-C10 -> 446284.52
A12: То же, млн ₽/год | C12: =C11*12/10^6 -> 5.3554143
